Workbook

Sheet Parts
A1: Pinball machine - parts inventory (every version I found in your fablab folder)
A2: How: click a yellow cell in column C and pick Used or Not used. Blank = not decided yet. Rows turn green (used) or grey (not used); the Summary tab counts for you.
A3: Tip: filter column C by 'Used' to get your final parts list. Don't sort - the preview pictures stay where they are. Hints are clues, not proof (a part can be sliced and still never used).
A4: Component | B4: Version | C4: USED IN FINAL MACHINE? | D4: FreeCAD preview | E4: Part / outline preview | F4: What it is (my guess) | G4: Hints from your files | H4: Last edited | I4: Your notes | J4: Made how | K4: Group | L4: Files found
A5: Box (early) | B5: BoxProject (Feb) | C5: Not used | F5: First simple open box, made before the finger-joint version. | G5: - | H5: 46080 | J5: Laser cut | K5: Box & playfield (wood) | L5: BoxProject.FCStd
A6: Box finger-joint test | B6: Bottom finger (Feb) | C6: Not used | F6: Early test of a finger-joint bottom panel. | G6: - | H6: 46081 | J6: Laser cut | K6: Box & playfield (wood) | L6: bocx bottomfinger.FCStd BottomBox Finger.svg
A7: Box (finger joints) | B7: boxProjectFinger | C7: Used | F7: Main wooden box with finger joints: back, bottom, front, left/right sides, long and short legs. 6 mm MDF, laser cut (report). Preview tiles (top-left to bottom-right): SideFingerRightSketch007, BackSketch004, SideFingerLeft]Sketch001, BottomSketch | G7: - Has an Illustrator (.ai) file, i.e. prepared for the laser cutter | H7: 46178 | J7: Laser cut | K7: Box & playfield (wood) | L7: boxProjectFinger.FCStd boxProjectFinger-BackSketch004.svg boxProjectFinger-BottomSketch.svg boxProjectFinger-FrontFingerSketch002.svg boxProjectFinger-LegLong3.ai boxProjectFinger-LegShort3.ai boxProjectFinger-SideFingerLeft]Pad008.svg + 2 more files
A8: Box side panel | B8: left side (SVG) | C8: Not used | F8: Side panel outline. SVG only, no FreeCAD source found. | G8: - | H8: 46134 | J8: Laser cut | K8: Box & playfield (wood) | L8: left side.svg
A9: Box side panel | B9: Dimensions image | C9: Not used | F9: Reference picture with the side dimensions. | G9: - | H9: 46066 | J9: Reference | K9: Box & playfield (wood) | L9: SideBoxDimensions.png
A10: Playfield plate | B10: middle part | C10: Not used | F10: First outline of the playfield plate. | G10: - | H10: 46136 | J10: Laser cut | K10: Box & playfield (wood) | L10: middle part.FCStd middle part-BodySketch.svg
A11: Playfield plate | B11: Sketch base Middle | C11: Not used | F11: Second sketch of the playfield plate. | G11: - | H11: 46136 | J11: Laser cut | K11: Box & playfield (wood) | L11: Sketch base Middle.FCStd
A12: Playfield plate | B12: Sketch Middle New | C12: Not used | F12: Third sketch of the playfield plate. | G12: - | H12: 46136 | J12: Laser cut | K12: Box & playfield (wood) | L12: Sketch Middle New.FCStd
A13: Playfield plate | B13: SketchMiddleNew | C13: Used | F13: Playfield layout with flippers, targets, walls and slide. Laser-engraved as an assembly guide (report). | G13: - Also copied into your 'Prototyping Pinball' folder - Has an Illustrator (.ai) file, i.e. prepared for the laser cutter - Most recently edited version of this component | H13: 46178 | J13: Laser cut | K13: Box & playfield (wood) | L13: SketchMiddleNew.FCStd SketchMiddleNew-Body.svg SketchMiddleNew-BodyBottomCover.svg SketchMiddleNew.ai SketchMiddleNew.svg Prototyping Pinball/ SketchMiddleNew.FCStd Prototyping Pinball/ SketchMiddleNew-BodyBottomCover.svg Prototyping Pinball/ SketchMiddleNew-BodyLoadShaftCover.svg
A14: Playfield plate | B14: Unnamed1 exports | F14: Exports of body sketch, bottom cover, load-shaft cover and a triangle target STL. The FreeCAD file was renamed, source not found. | G14: - Has an Illustrator (.ai) file, i.e. prepared for the laser cutter - No FreeCAD source file in the folder | H14: 46171 | J14: Laser cut + 3D print | K14: Box & playfield (wood) | L14: Unnamed1-BodySketch.svg Unnamed1-BottomCover.svg Unnamed1-LoadShaftCover.ai Unnamed1-LoadShaftCover.svg Unnamed1-TrojuholnikHitTarget.stl
A15: Load-shaft cover | B15: CoverShaftLoad | F15: Cover over the ball-loading shaft. | G15: - | H15: 46169 | J15: Laser cut | K15: Box & playfield (wood) | L15: CoverShaftLoad.FCStd
A16: Curved wall (inner) | B16: innercurve | C16: Used | F16: Inner curved wall pieces (8 strips in the SVG). | G16: - In your 'LaserCutterPinball' folder (Illustrator files for the laser cutter) | H16: 46160 | J16: Laser cut | K16: Walls & lanes (wood) | L16: innercurve.svg LaserCutterPinball/ innercurve.ai
A17: Curved wall (outer) | B17: outercurve | C17: Used | F17: Outer curved wall pieces. | G17: - In your 'LaserCutterPinball' folder (Illustrator files for the laser cutter) | H17: 46160 | J17: Laser cut | K17: Walls & lanes (wood) | L17: outercurve.svg LaserCutterPinball/ outercurve.ai
A18: Loading wall | B18: WallLoading | C18: Used | F18: Wall along the ball-loading lane. | G18: - In your 'LaserCutterPinball' folder (Illustrator files for the laser cutter) | H18: 46160 | J18: Laser cut | K18: Walls & lanes (wood) | L18: WallLoading.svg LaserCutterPinball/ WallLoading.ai
A19: Top triangle wall | B19: WallTopTriangle | C19: Used | F19: Wall piece at the top triangle of the playfield. | G19: - Has an Illustrator (.ai) file, i.e. prepared for the laser cutter | H19: 46169 | J19: Laser cut | K19: Walls & lanes (wood) | L19: WallTopTriangle.FCStd WallTopTriangle-BodySketch.ai WallTopTriangle-BodySketch.svg
A20: Left wall (arms) | B20: LeftWallArms | C20: Used | F20: Wooden wall next to the flipper arms. | G20: - | H20: 46149 | J20: Laser cut | K20: Walls & lanes (wood) | L20: LeftWallArms.FCStd LeftWallArms-BodySketch.svg
A21: Flipper side wood | B21: Left (LeftSideRucickyDrevo) | C21: Used | F21: Wood side piece for the left flipper ('drevo' = wood). | G21: - | H21: 46148 | J21: Laser cut | K21: Walls & lanes (wood) | L21: LeftSideRucickyDrevo.FCStd LeftSideRucickyDrevo-BodySketch.svg
A22: Flipper side wood | B22: Right (RightSideRucickyDrevo) | C22: Used | F22: Wood side piece for the right flipper. | G22: - | H22: 46148 | J22: Laser cut | K22: Walls & lanes (wood) | L22: RightSideRucickyDrevo.FCStd RightSideRucickyDrevo-BodySketch.svg
A23: Wall left flipper | B23: WallLeftRucicky | F23: Wall outline near the left flipper. The STL is empty, only the SVG has data. | G23: - Empty STL (no geometry): WallLeftRucicky.stl - No FreeCAD source file in the folder | H23: 46160 | J23: Laser cut | K23: Walls & lanes (wood) | L23: WallLeftRucicky.stl WallLeftRucicky.svg
A24: Loading lane wood | B24: LoadingWood | F24: First wooden guide wall for the ball storage lane (report). | G24: - | H24: 46145 | J24: Laser cut | K24: Walls & lanes (wood) | L24: LoadingWood.FCStd
A25: Loading lane wood | B25: LoadingWoodLong | F25: Long guide wall of the ball lane. | G25: - | H25: 46149 | J25: Laser cut | K25: Walls & lanes (wood) | L25: LoadingWoodLong.FCStd LoadingWoodLong-BodySketch.svg
A26: Loading lane wood | B26: LoadingWoodShort | F26: Short guide wall of the ball lane. | G26: - | H26: 46149 | J26: Laser cut | K26: Walls & lanes (wood) | L26: LoadingWoodShort.FCStd LoadingWoodShort-BodySketch.svg
A27: Ball chamber wood | B27: ChamberBottomShort | F27: Short bottom piece of the ball chamber. | G27: - | H27: 46145 | J27: Laser cut | K27: Walls & lanes (wood) | L27: ChamberBottomShort.FCStd
A28: Ball chamber wood | B28: ChamberLongWood | F28: Long wooden piece of the ball chamber. | G28: - | H28: 46145 | J28: Laser cut | K28: Walls & lanes (wood) | L28: ChamberLongWood.FCStd
A29: Ball chamber wood | B29: ChamberTopCurve | F29: Curved top piece of the ball chamber. | G29: - | H29: 46145 | J29: Laser cut | K29: Walls & lanes (wood) | L29: ChamberTopCurve.FCStd
A30: Flipper lever | B30: RucickaBolt | C30: Not used | F30: First flipper: nut-and-bolt pivot (report). Two shapes exported: Rucicka and RucickaNew. Preview tiles (top-left to bottom-right): Rucicka, RucickaNew | G30: - Sliced for printing: RucickaNew 37m | H30: 46135 | J30: 3D print | K30: Flippers & drive | L30: RucickaBolt.FCStd RucickaBolt-Rucicka.stl RucickaBolt-RucickaNew.stl RucickaBolt-RucickaNew.bgcode [0.2 mm, 37m]
A31: Flipper lever | B31: RucickaNovaV3 (STL only) | C31: Not used | F31: 'Nova' = new flipper design. STL export only, no FreeCAD source. | G31: - No FreeCAD source file in the folder | H31: 46139 | J31: 3D print | K31: Flippers & drive | L31: RucickaNovaV3.stl
A32: Flipper lever | B32: RucickaBoltV4 | C32: Not used | F32: Bolt-pivot flipper, 4th version. | G32: - | H32: 46140 | J32: 3D print | K32: Flippers & drive | L32: RucickaBoltV4.FCStd RucickaBoltV4-Rucicka.stl
A33: Flipper lever | B33: RucickaNovaV4 (STL only) | C33: Not used | F33: 'Nova' flipper, 4th version. STL export only. | G33: - No FreeCAD source file in the folder | H33: 46140 | J33: 3D print | K33: Flippers & drive | L33: RucickaNovaV4.stl
A34: Flipper lever | B34: RucickaNova | C34: Used | F34: Newest flipper file. Final flipper used a steel rod with a D-shaped end (report). | G34: - Most recently edited version of this component | H34: 46154 | J34: 3D print | K34: Flippers & drive | L34: RucickaNova.FCStd RucickaNova-Rucicka.stl
A35: Flipper drive adapter | B35: V1 (BottomArmAdapter) | C35: Not used | F35: Adapter under the playfield linking the solenoid arm to the flipper rod (report). | G35: - Empty STL (no geometry): BottomArmAdapter-BodySketch009.stl | H35: 46136 | J35: 3D print | K35: Flippers & drive | L35: BottomArmAdapter.FCStd BottomArmAdapter-Body.stl BottomArmAdapter-BodySketch009.stl
A36: Flipper drive adapter | B36: V2 | C36: Not used | F36: Adapter under the playfield, 2nd version. | G36: - | H36: 46135 | J36: 3D print | K36: Flippers & drive | L36: BottomArmAdapterV2.FCStd BottomArmAdapterV2-Body.stl
A37: Flipper drive adapter | B37: V3 | C37: Not used | F37: Adapter under the playfield, 3rd version. | G37: - | H37: 46142 | J37: 3D print | K37: Flippers & drive | L37: BottomArmAdapterV3.FCStd BottomArmAdapterV3-Body.stl
A38: Flipper drive adapter | B38: V4 | C38: Not used | F38: Adapter under the playfield, 4th version (split into Adapter, Body and Connector). Preview tiles (top-left to bottom-right): Adapter, Body, Connector | G38: - | H38: 46142 | J38: 3D print | K38: Flippers & drive | L38: BottomArmAdapterV4.FCStd BottomArmAdapterV4-Adapter.stl BottomArmAdapterV4-Body.stl BottomArmAdapterV4-Connector.stl
A39: Flipper drive adapter | B39: V5 (BottomAdapterV5) | C39: Not used | F39: Adapter under the playfield, 5th version. No STL exported. | G39: - Most recently edited version of this component | H39: 46146 | J39: 3D print | K39: Flippers & drive | L39: BottomAdapterV5.FCStd
A40: Flipper solenoid assembly | B40: AdapterArmsV1 | C40: Used | F40: Base + holder, arm, sleeve, circle and connector for the flipper mechanism. Preview tiles (top-left to bottom-right): Base+Holder, Sleeve, Circle, Arm (+1 more part) | G40: - Sliced for printing: Base+Holder 28m - Empty STL (no geometry): AdapterArmsV1-Base+HolderSketch.stl | H40: 46161 | J40: 3D print | K40: Flippers & drive | L40: AdapterArmsV1.FCStd AdapterArmsV1-Arm.stl AdapterArmsV1-Base+Holder.stl AdapterArmsV1-Base+Holder.svg AdapterArmsV1-Base+HolderSketch.stl AdapterArmsV1-Base+Holder.bgcode [0.2 mm, 28m] AdapterArmsV1-Circle.stl + 2 more files
...

Sheet Summary
A1: Pinball parts - summary (updates by itself as you click on the Parts tab)
A3: Total part versions | B3: =COUNTA(Parts!$A$5:$A$82) -> 78
A4: Marked Used | B4: =COUNTIF(Parts!$C$5:$C$82,"Used") -> 32
A5: Marked Not used | B5: =COUNTIF(Parts!$C$5:$C$82,"Not used") -> 36
A6: Not decided yet | B6: =B3-B4-B5 -> 10
A7: Progress (decided / total) | B7: =IF(B3=0,0,(B4+B5)/B3) -> 0.87179487
A10: Group | B10: Component | C10: Versions | D10: Used | E10: Not used | F10: Not decided
A11: Box & playfield (wood) | B11: Box (early) | C11: =COUNTIF(Parts!$A$5:$A$82,B11) -> 1 | D11: =COUNTIFS(Parts!$A$5:$A$82,B11,Parts!$C$5:$C$82,"Used") -> 0 | E11: =COUNTIFS(Parts!$A$5:$A$82,B11,Parts!$C$5:$C$82,"Not used") -> 1 | F11: =C11-D11-E11 -> 0
A12: Box & playfield (wood) | B12: Box finger-joint test | C12: =COUNTIF(Parts!$A$5:$A$82,B12) -> 1 | D12: =COUNTIFS(Parts!$A$5:$A$82,B12,Parts!$C$5:$C$82,"Used") -> 0 | E12: =COUNTIFS(Parts!$A$5:$A$82,B12,Parts!$C$5:$C$82,"Not used") -> 1 | F12: =C12-D12-E12 -> 0
A13: Box & playfield (wood) | B13: Box (finger joints) | C13: =COUNTIF(Parts!$A$5:$A$82,B13) -> 1 | D13: =COUNTIFS(Parts!$A$5:$A$82,B13,Parts!$C$5:$C$82,"Used") -> 1 | E13: =COUNTIFS(Parts!$A$5:$A$82,B13,Parts!$C$5:$C$82,"Not used") -> 0 | F13: =C13-D13-E13 -> 0
A14: Box & playfield (wood) | B14: Box side panel | C14: =COUNTIF(Parts!$A$5:$A$82,B14) -> 2 | D14: =COUNTIFS(Parts!$A$5:$A$82,B14,Parts!$C$5:$C$82,"Used") -> 0 | E14: =COUNTIFS(Parts!$A$5:$A$82,B14,Parts!$C$5:$C$82,"Not used") -> 2 | F14: =C14-D14-E14 -> 0
A15: Box & playfield (wood) | B15: Playfield plate | C15: =COUNTIF(Parts!$A$5:$A$82,B15) -> 5 | D15: =COUNTIFS(Parts!$A$5:$A$82,B15,Parts!$C$5:$C$82,"Used") -> 1 | E15: =COUNTIFS(Parts!$A$5:$A$82,B15,Parts!$C$5:$C$82,"Not used") -> 3 | F15: =C15-D15-E15 -> 1
A16: Box & playfield (wood) | B16: Load-shaft cover | C16: =COUNTIF(Parts!$A$5:$A$82,B16) -> 1 | D16: =COUNTIFS(Parts!$A$5:$A$82,B16,Parts!$C$5:$C$82,"Used") -> 0 | E16: =COUNTIFS(Parts!$A$5:$A$82,B16,Parts!$C$5:$C$82,"Not used") -> 0 | F16: =C16-D16-E16 -> 1
A17: Walls & lanes (wood) | B17: Curved wall (inner) | C17: =COUNTIF(Parts!$A$5:$A$82,B17) -> 1 | D17: =COUNTIFS(Parts!$A$5:$A$82,B17,Parts!$C$5:$C$82,"Used") -> 1 | E17: =COUNTIFS(Parts!$A$5:$A$82,B17,Parts!$C$5:$C$82,"Not used") -> 0 | F17: =C17-D17-E17 -> 0
A18: Walls & lanes (wood) | B18: Curved wall (outer) | C18: =COUNTIF(Parts!$A$5:$A$82,B18) -> 1 | D18: =COUNTIFS(Parts!$A$5:$A$82,B18,Parts!$C$5:$C$82,"Used") -> 1 | E18: =COUNTIFS(Parts!$A$5:$A$82,B18,Parts!$C$5:$C$82,"Not used") -> 0 | F18: =C18-D18-E18 -> 0
A19: Walls & lanes (wood) | B19: Loading wall | C19: =COUNTIF(Parts!$A$5:$A$82,B19) -> 1 | D19: =COUNTIFS(Parts!$A$5:$A$82,B19,Parts!$C$5:$C$82,"Used") -> 1 | E19: =COUNTIFS(Parts!$A$5:$A$82,B19,Parts!$C$5:$C$82,"Not used") -> 0 | F19: =C19-D19-E19 -> 0
A20: Walls & lanes (wood) | B20: Top triangle wall | C20: =COUNTIF(Parts!$A$5:$A$82,B20) -> 1 | D20: =COUNTIFS(Parts!$A$5:$A$82,B20,Parts!$C$5:$C$82,"Used") -> 1 | E20: =COUNTIFS(Parts!$A$5:$A$82,B20,Parts!$C$5:$C$82,"Not used") -> 0 | F20: =C20-D20-E20 -> 0
A21: Walls & lanes (wood) | B21: Left wall (arms) | C21: =COUNTIF(Parts!$A$5:$A$82,B21) -> 1 | D21: =COUNTIFS(Parts!$A$5:$A$82,B21,Parts!$C$5:$C$82,"Used") -> 1 | E21: =COUNTIFS(Parts!$A$5:$A$82,B21,Parts!$C$5:$C$82,"Not used") -> 0 | F21: =C21-D21-E21 -> 0
A22: Walls & lanes (wood) | B22: Flipper side wood | C22: =COUNTIF(Parts!$A$5:$A$82,B22) -> 2 | D22: =COUNTIFS(Parts!$A$5:$A$82,B22,Parts!$C$5:$C$82,"Used") -> 2 | E22: =COUNTIFS(Parts!$A$5:$A$82,B22,Parts!$C$5:$C$82,"Not used") -> 0 | F22: =C22-D22-E22 -> 0
... A50: Unclear - please check | B50: Scratch / test file | C50: =COUNTIF(Parts!$A$5:$A$82,B50) -> 8 | D50: =COUNTIFS(Parts!$A$5:$A$82,B50,Parts!$C$5:$C$82,"Used") -> 0 | E50: =COUNTIFS(Parts!$A$5:$A$82,B50,Parts!$C$5:$C$82,"Not used") -> 8 | F50: =C50-D50-E50 -> 0
B51: Total | C51: =SUM(C11:C50) -> 78 | D51: =SUM(D11:D50) -> 32 | E51: =SUM(E11:E50) -> 36 | F51: =SUM(F11:F50) -> 10

Sheet Not pinball
A1: Files I left out of the pinball list - tell me if I got one wrong
A3: File / folder | B3: What it is | C3: Why I left it out | D3: It IS pinball?
A4: fablab.ino | B4: Arduino dice thrower with an LCD (Nov 2025) | C4: Small class exercise, no relation to the pinball.
A5: bench01.FCStd + bench01-Pad004_tab.dxf | B5: Bench model + DXF (Feb 2026) | C5: FreeCAD tutorial-style project from before the pinball started.
A6: basePartTurotial.FCStd | B6: Bracket from a tutorial (27 Feb) | C6: Tutorial file ('Turotial').
A7: RandomTurorial1.FCStd | B7: Cylinder on a base plate (1 May) | C7: Tutorial file.
A8: PracticePart10.FCStd | B8: Practice part (5 Jun) | C8: Practice part, dated after the machine was built.
A9: PracticePart11.FCStd | B9: Practice part (5 Jun) | C9: Practice part, dated after the machine was built.
A10: adadad.FCStd | B10: Small wedge (27 Feb) | C10: Same day as the tutorial file, looks like a keyboard-mash test.
A11: FabLAB All canon/ (folder) | B11: Ping pong launcher files (Dec 2025 - Jan 2026) | C11: The launcher project you decided to leave out of the portfolio.
A12: Fusion challange/ (folder) | B12: Lost & Found locker + Mental Hospital Museum | C12: Different projects.
A13: INenOUT/ (folder) | B13: Arduino class material and exercises | C13: Different course material.
A14: Prototyping/ (folder) | B14: Paper cube lamp, Billboard scene, old course portfolio | C14: Different projects.

Sheet How to use
A1: How to use this workbook
A3: What to edit | B3: Only the yellow cells: column C on the Parts tab (Used / Not used), your notes in column I, and column D on the Not pinball tab. Everything else is filled in for you.
A4: Example | B4: Component 'Hit target (top)': click 'Used' on V4 and 'Not used' on V1, V2, V3 and V5. The row turns green or grey and the Summary tab updates.
A5: Blank cells | B5: A blank means 'not decided yet'. The Summary tab shows how many are still open.
A6: Filter, don't sort | B6: Use the arrows in the header row (for example column C = Used). Sorting would separate the rows from their pictures.
A7: Previews | B7: Left: the picture FreeCAD saved in the file (sometimes cropped or empty). Right: my render of the exported STL parts (up to 4 tiles, largest part first; names are listed in the description) or of the laser-cut SVG outline.
A8: Hints column | B8: 'Sliced for printing' = a .bgcode file exists (a print file for the Prusa MK4S). 'MondayPrint' = the file sits in your Prototyping Pinball/MondayPrint folder. 'Also copied into Prototyping Pinball' = you copied it into that folder, which looks like a final set. 'Most recently edited' = the newest save among that component's versions. These are clues, not proof.
A9: What is my guess | B9: The descriptions come from file names, the previews, your Prototyping report and your LoadingAll.png diagram. Slovak words I decoded: Rucicka = flipper lever, Drevo = wood, Zabrana = barrier, Obmedzovac = limiter, Podlozka = washer, Trojuholnik = triangle, Uholnik = angle piece. Correct anything wrong in the notes column.
A10: Scope | B10: Built from C:\Users\jakub\Desktop\KdG\fablab (root files and the Prototyping Pinball folder). FreeCAD autosave backups (.FCBak) are ignored.
